{
    "url": "https://api.github.com/repos/pallets/flask/issues/2194",
    "repository_url": "https://api.github.com/repos/pallets/flask",
    "labels_url": "https://api.github.com/repos/pallets/flask/issues/2194/labels{/name}",
    "comments_url": "https://api.github.com/repos/pallets/flask/issues/2194/comments",
    "events_url": "https://api.github.com/repos/pallets/flask/issues/2194/events",
    "html_url": "https://github.com/pallets/flask/issues/2194",
    "id": 211119451,
    "node_id": "MDU6SXNzdWUyMTExMTk0NTE=",
    "number": 2194,
    "title": "Issue with installing app debugger",
    "user": {
        "login": "JLinthorst",
        "id": 26117442,
        "node_id": "MDQ6VXNlcjI2MTE3NDQy",
        "avatar_url": "https://avatars1.githubusercontent.com/u/26117442?v=4",
        "gravatar_id": "",
        "url": "https://api.github.com/users/JLinthorst",
        "html_url": "https://github.com/JLinthorst",
        "followers_url": "https://api.github.com/users/JLinthorst/followers",
        "following_url": "https://api.github.com/users/JLinthorst/following{/other_user}",
        "gists_url": "https://api.github.com/users/JLinthorst/gists{/gist_id}",
        "starred_url": "https://api.github.com/users/JLinthorst/starred{/owner}{/repo}",
        "subscriptions_url": "https://api.github.com/users/JLinthorst/subscriptions",
        "organizations_url": "https://api.github.com/users/JLinthorst/orgs",
        "repos_url": "https://api.github.com/users/JLinthorst/repos",
        "events_url": "https://api.github.com/users/JLinthorst/events{/privacy}",
        "received_events_url": "https://api.github.com/users/JLinthorst/received_events",
        "type": "User",
        "site_admin": false
    },
    "labels": [],
    "state": "closed",
    "locked": false,
    "assignee": null,
    "assignees": [],
    "milestone": null,
    "comments": 2,
    "created_at": "2017-03-01T15:42:59Z",
    "updated_at": "2017-03-12T19:39:10Z",
    "closed_at": "2017-03-12T19:39:10Z",
    "author_association": "NONE",
    "body": "I tried to install the app debugger, to make my webapp run instantly when I change the code, with:\r\napp.run(debug=True)\r\n\r\nHowever, I get the Error message below. Does someone know how to fix this?\r\nMany thanks!\r\n\r\n```pythontb\r\n* Restarting with stat\r\n* Debugger is active!\r\n* Debugger pin code: xx\r\nException in thread Thread-1:\r\nTraceback (most recent call last):\r\n File \"C:\\Users\\josep\\Anaconda3\\lib\\threading.py\", line 914, in _bootstrap_inner\r\n   self.run()\r\n File \"C:\\Users\\josep\\Anaconda3\\lib\\threading.py\", line 862, in run\r\n   self._target(*self._args, **self._kwargs)\r\n File \"C:\\Users\\josep\\Anaconda3\\lib\\site-packages\\werkzeug\\serving.py\", line 656, in i\r\n   fd=fd)\r\n File \"C:\\Users\\josep\\Anaconda3\\lib\\site-packages\\werkzeug\\serving.py\", line 550, in m\r\n   passthrough_errors, ssl_context, fd=fd)\r\n File \"C:\\Users\\josep\\Anaconda3\\lib\\site-packages\\werkzeug\\serving.py\", line 462, in _\r\n   socket.SOCK_STREAM)\r\n File \"C:\\Users\\josep\\Anaconda3\\lib\\socket.py\", line 450, in fromfd\r\n   nfd = dup(fd)\r\nOSError: [WinError 10038] An operation was attempted on something that is not a socket\r\n```",
    "comments_inline": [
        {
            "url": "https://api.github.com/repos/pallets/flask/issues/comments/283390081",
            "html_url": "https://github.com/pallets/flask/issues/2194#issuecomment-283390081",
            "issue_url": "https://api.github.com/repos/pallets/flask/issues/2194",
            "id": 283390081,
            "node_id": "MDEyOklzc3VlQ29tbWVudDI4MzM5MDA4MQ==",
            "user": {
                "login": "alexpantyukhin",
                "id": 6513121,
                "node_id": "MDQ6VXNlcjY1MTMxMjE=",
                "avatar_url": "https://avatars3.githubusercontent.com/u/6513121?v=4",
                "gravatar_id": "",
                "url": "https://api.github.com/users/alexpantyukhin",
                "html_url": "https://github.com/alexpantyukhin",
                "followers_url": "https://api.github.com/users/alexpantyukhin/followers",
                "following_url": "https://api.github.com/users/alexpantyukhin/following{/other_user}",
                "gists_url": "https://api.github.com/users/alexpantyukhin/gists{/gist_id}",
                "starred_url": "https://api.github.com/users/alexpantyukhin/starred{/owner}{/repo}",
                "subscriptions_url": "https://api.github.com/users/alexpantyukhin/subscriptions",
                "organizations_url": "https://api.github.com/users/alexpantyukhin/orgs",
                "repos_url": "https://api.github.com/users/alexpantyukhin/repos",
                "events_url": "https://api.github.com/users/alexpantyukhin/events{/privacy}",
                "received_events_url": "https://api.github.com/users/alexpantyukhin/received_events",
                "type": "User",
                "site_admin": false
            },
            "created_at": "2017-03-01T16:26:06Z",
            "updated_at": "2017-03-01T16:26:06Z",
            "author_association": "CONTRIBUTOR",
            "body": "What is the python version do you use?"
        },
        {
            "url": "https://api.github.com/repos/pallets/flask/issues/comments/285893678",
            "html_url": "https://github.com/pallets/flask/issues/2194#issuecomment-285893678",
            "issue_url": "https://api.github.com/repos/pallets/flask/issues/2194",
            "id": 285893678,
            "node_id": "MDEyOklzc3VlQ29tbWVudDI4NTg5MzY3OA==",
            "user": {
                "login": "aaossa",
                "id": 10425834,
                "node_id": "MDQ6VXNlcjEwNDI1ODM0",
                "avatar_url": "https://avatars2.githubusercontent.com/u/10425834?v=4",
                "gravatar_id": "",
                "url": "https://api.github.com/users/aaossa",
                "html_url": "https://github.com/aaossa",
                "followers_url": "https://api.github.com/users/aaossa/followers",
                "following_url": "https://api.github.com/users/aaossa/following{/other_user}",
                "gists_url": "https://api.github.com/users/aaossa/gists{/gist_id}",
                "starred_url": "https://api.github.com/users/aaossa/starred{/owner}{/repo}",
                "subscriptions_url": "https://api.github.com/users/aaossa/subscriptions",
                "organizations_url": "https://api.github.com/users/aaossa/orgs",
                "repos_url": "https://api.github.com/users/aaossa/repos",
                "events_url": "https://api.github.com/users/aaossa/events{/privacy}",
                "received_events_url": "https://api.github.com/users/aaossa/received_events",
                "type": "User",
                "site_admin": false
            },
            "created_at": "2017-03-11T19:28:54Z",
            "updated_at": "2017-03-11T20:23:07Z",
            "author_association": "NONE",
            "body": "I have the same error with this code:\r\n\r\n```python\r\nimport flask\r\n\r\napp = flask.Flask(__name__)\r\n\r\n\r\n@app.route(\"/\")\r\ndef hello_world():\r\n    return \"Hello, World!\"\r\n\r\nif __name__ == '__main__':\r\n    app.run(debug=True)\r\n```\r\n\r\nTraceback:\r\n\r\n```\r\n * Running on http://127.0.0.1:5000/ (Press CTRL+C to quit)\r\n * Restarting with stat\r\n * Debugger is active!\r\n * Debugger PIN: 184-245-196\r\nException in thread Thread-1:\r\nTraceback (most recent call last):\r\n  File \"C:\\Program Files\\Python35\\lib\\threading.py\", line 914, in _bootstrap_inner\r\n    self.run()\r\n  File \"C:\\Program Files\\Python35\\lib\\threading.py\", line 862, in run\r\n    self._target(*self._args, **self._kwargs)\r\n  File \"C:\\Program Files\\Python35\\lib\\site-packages\\werkzeug\\serving.py\", line 696, in inner\r\n    fd=fd)\r\n  File \"C:\\Program Files\\Python35\\lib\\site-packages\\werkzeug\\serving.py\", line 590, in make_server\r\n    passthrough_errors, ssl_context, fd=fd)\r\n  File \"C:\\Program Files\\Python35\\lib\\site-packages\\werkzeug\\serving.py\", line 499, in __init__\r\n    socket.SOCK_STREAM)\r\n  File \"C:\\Program Files\\Python35\\lib\\socket.py\", line 450, in fromfd\r\n    nfd = dup(fd)\r\nOSError: [WinError 10038] Se intent\u00f3 realizar una operaci\u00f3n en un elemento que no es un socket\r\n```\r\n\r\nEven in a virtual environment:\r\n\r\n```\r\n(venv) PATH>python --version\r\nPython 3.5.2\r\n\r\n(venv) PATH>pip list\r\nDEPRECATION: The default format will switch to columns in the future. You can use --format=(legacy|columns) (or define a format=(legacy|columns) in your pip.conf under the [list] section) to disable this warning.\r\nappdirs (1.4.3)\r\nclick (6.7)\r\nFlask (0.12)\r\nitsdangerous (0.24)\r\nJinja2 (2.9.5)\r\nMarkupSafe (1.0)\r\npackaging (16.8)\r\npip (9.0.1)\r\npyparsing (2.2.0)\r\nsetuptools (34.3.2)\r\nsix (1.10.0)\r\nWerkzeug (0.12)\r\nwheel (0.29.0)\r\n\r\n(venv) PATH>python demo.py\r\n * Running on http://127.0.0.1:5000/ (Press CTRL+C to quit)\r\n * Restarting with stat\r\n * Debugger is active!\r\n * Debugger PIN: 196-189-207\r\nException in thread Thread-1:\r\nTraceback (most recent call last):\r\n  File \"c:\\program files\\python35\\Lib\\threading.py\", line 914, in _bootstrap_inner\r\n    self.run()\r\n  File \"c:\\program files\\python35\\Lib\\threading.py\", line 862, in run\r\n    self._target(*self._args, **self._kwargs)\r\n  File \"PATH\\venv\\lib\\site-packages\\werkzeug\\serving.py\", line 696, in inner\r\n    fd=fd)\r\n  File \"PATH\\venv\\lib\\site-packages\\werkzeug\\serving.py\", line 590, in make_server\r\n    passthrough_errors, ssl_context, fd=fd)\r\n  File \"PATH\\venv\\lib\\site-packages\\werkzeug\\serving.py\", line 499, in __init__\r\n    socket.SOCK_STREAM)\r\n  File \"c:\\program files\\python35\\Lib\\socket.py\", line 450, in fromfd\r\n    nfd = dup(fd)\r\nOSError: [WinError 10038] Se intent\u00f3 realizar una operaci\u00f3n en un elemento que no es un socket\r\n```\r\n\r\nIt seems like something changed in Flask or Werkzeug recently. I don't know what's happening but with this \"bug\" I can't work on a Windows machine using debug mode.\r\n\r\n**EDIT @aaossa:** (Related: https://github.com/pallets/werkzeug/issues/993) It seems like Flask believes that opening a socket by file descriptor is possible [werkzeug/serving.py#L97], wich is determined by [werkzeug/serving.py#L723]. Finally, the problem falls to [python/socket.py#L460] and [python/socket.py#L632]. A few days ago this Flask debug mode worked, I only updated Flask and Werkzeug. I'll try to check if the problem comes from Flask, Werkzeug, Python or Windows.\r\n\r\n[werkzeug/serving.py#L97]: https://github.com/pallets/werkzeug/blob/master/werkzeug/serving.py#L97\r\n[werkzeug/serving.py#L723]: https://github.com/pallets/werkzeug/blob/master/werkzeug/serving.py#L723\r\n[python/socket.py#L460]: https://github.com/python/cpython/blob/master/Lib/socket.py#L460\r\n[python/socket.py#L632]: https://github.com/python/cpython/blob/master/Lib/socket.py#L632"
        }
    ]
}