{
    "url": "https://api.github.com/repos/pallets/flask/issues/2767",
    "repository_url": "https://api.github.com/repos/pallets/flask",
    "labels_url": "https://api.github.com/repos/pallets/flask/issues/2767/labels{/name}",
    "comments_url": "https://api.github.com/repos/pallets/flask/issues/2767/comments",
    "events_url": "https://api.github.com/repos/pallets/flask/issues/2767/events",
    "html_url": "https://github.com/pallets/flask/issues/2767",
    "id": 321399556,
    "node_id": "MDU6SXNzdWUzMjEzOTk1NTY=",
    "number": 2767,
    "title": "[Regression] Test client's response.status_code is always 500 when an exception is raised",
    "user": {
        "login": "Depau",
        "id": 1151321,
        "node_id": "MDQ6VXNlcjExNTEzMjE=",
        "avatar_url": "https://avatars2.githubusercontent.com/u/1151321?v=4",
        "gravatar_id": "",
        "url": "https://api.github.com/users/Depau",
        "html_url": "https://github.com/Depau",
        "followers_url": "https://api.github.com/users/Depau/followers",
        "following_url": "https://api.github.com/users/Depau/following{/other_user}",
        "gists_url": "https://api.github.com/users/Depau/gists{/gist_id}",
        "starred_url": "https://api.github.com/users/Depau/starred{/owner}{/repo}",
        "subscriptions_url": "https://api.github.com/users/Depau/subscriptions",
        "organizations_url": "https://api.github.com/users/Depau/orgs",
        "repos_url": "https://api.github.com/users/Depau/repos",
        "events_url": "https://api.github.com/users/Depau/events{/privacy}",
        "received_events_url": "https://api.github.com/users/Depau/received_events",
        "type": "User",
        "site_admin": false
    },
    "labels": [],
    "state": "closed",
    "locked": false,
    "assignee": null,
    "assignees": [],
    "milestone": null,
    "comments": 1,
    "created_at": "2018-05-09T01:27:44Z",
    "updated_at": "2018-05-09T13:27:03Z",
    "closed_at": "2018-05-09T13:27:03Z",
    "author_association": "NONE",
    "body": "### Expected Behavior\r\nWhat used to happen before, i.e. on\r\n\r\n```python\r\nraise NotFound()\r\n```\r\n\r\nthe test client's response.status_code should be `404`.\r\n\r\n### Actual Behavior\r\n\r\nIt's always `500`.\r\n\r\n### Environment\r\n\r\nSee my failing Travis CI builds:\r\n- https://travis-ci.org/poliedro-polimi/Crowdfunding-Backend\r\n- One of the tests that fails because of this issue: [link](https://github.com/poliedro-polimi/Crowdfunding-Backend/blob/master/tests/test_views.py#L157)\r\n- Code that makes it fail: [link](https://github.com/poliedro-polimi/Crowdfunding-Backend/blob/master/poliedro_donate/blueprints/donations.py#L60)\r\n\r\n* Python version: >3.5, pypy3 (not tested on other versions)\r\n* Flask version: 1.0.2 from pypi (worked as expected in 0.12.2)\r\n* Werkzeug version: 0.14.1\r\n",
    "comments_inline": [
        {
            "url": "https://api.github.com/repos/pallets/flask/issues/comments/387604617",
            "html_url": "https://github.com/pallets/flask/issues/2767#issuecomment-387604617",
            "issue_url": "https://api.github.com/repos/pallets/flask/issues/2767",
            "id": 387604617,
            "node_id": "MDEyOklzc3VlQ29tbWVudDM4NzYwNDYxNw==",
            "user": {
                "login": "davidism",
                "id": 1242887,
                "node_id": "MDQ6VXNlcjEyNDI4ODc=",
                "avatar_url": "https://avatars1.githubusercontent.com/u/1242887?v=4",
                "gravatar_id": "",
                "url": "https://api.github.com/users/davidism",
                "html_url": "https://github.com/davidism",
                "followers_url": "https://api.github.com/users/davidism/followers",
                "following_url": "https://api.github.com/users/davidism/following{/other_user}",
                "gists_url": "https://api.github.com/users/davidism/gists{/gist_id}",
                "starred_url": "https://api.github.com/users/davidism/starred{/owner}{/repo}",
                "subscriptions_url": "https://api.github.com/users/davidism/subscriptions",
                "organizations_url": "https://api.github.com/users/davidism/orgs",
                "repos_url": "https://api.github.com/users/davidism/repos",
                "events_url": "https://api.github.com/users/davidism/events{/privacy}",
                "received_events_url": "https://api.github.com/users/davidism/received_events",
                "type": "User",
                "site_admin": false
            },
            "created_at": "2018-05-09T02:55:23Z",
            "updated_at": "2018-05-09T02:55:23Z",
            "author_association": "MEMBER",
            "body": "I can't reproduce the issue. Please include a minimal example here to demonstrate the issue.\r\n\r\nThe following does not raise an assertion error:\r\n\r\n```python\r\nfrom werkzeug.exceptions import NotFound\r\nfrom flask import Flask\r\n\r\napp = Flask(__name__)\r\n\r\n@app.route('/')\r\ndef index():\r\n    raise NotFound()\r\n\r\nclient = app.test_client()\r\nresponse = client.get('/')\r\nassert response.status_code == 404\r\n```"
        }
    ]
}