{
    "url": "https://api.github.com/repos/pallets/flask/issues/2999",
    "repository_url": "https://api.github.com/repos/pallets/flask",
    "labels_url": "https://api.github.com/repos/pallets/flask/issues/2999/labels{/name}",
    "comments_url": "https://api.github.com/repos/pallets/flask/issues/2999/comments",
    "events_url": "https://api.github.com/repos/pallets/flask/issues/2999/events",
    "html_url": "https://github.com/pallets/flask/issues/2999",
    "id": 381923859,
    "node_id": "MDU6SXNzdWUzODE5MjM4NTk=",
    "number": 2999,
    "title": "Running flask in a thread with Kivy causes no requests to be printed out",
    "user": {
        "login": "s1113950",
        "id": 8314343,
        "node_id": "MDQ6VXNlcjgzMTQzNDM=",
        "avatar_url": "https://avatars3.githubusercontent.com/u/8314343?v=4",
        "gravatar_id": "",
        "url": "https://api.github.com/users/s1113950",
        "html_url": "https://github.com/s1113950",
        "followers_url": "https://api.github.com/users/s1113950/followers",
        "following_url": "https://api.github.com/users/s1113950/following{/other_user}",
        "gists_url": "https://api.github.com/users/s1113950/gists{/gist_id}",
        "starred_url": "https://api.github.com/users/s1113950/starred{/owner}{/repo}",
        "subscriptions_url": "https://api.github.com/users/s1113950/subscriptions",
        "organizations_url": "https://api.github.com/users/s1113950/orgs",
        "repos_url": "https://api.github.com/users/s1113950/repos",
        "events_url": "https://api.github.com/users/s1113950/events{/privacy}",
        "received_events_url": "https://api.github.com/users/s1113950/received_events",
        "type": "User",
        "site_admin": false
    },
    "labels": [],
    "state": "closed",
    "locked": false,
    "assignee": null,
    "assignees": [],
    "milestone": null,
    "comments": 14,
    "created_at": "2018-11-18T03:15:28Z",
    "updated_at": "2018-11-20T10:36:32Z",
    "closed_at": "2018-11-19T06:43:41Z",
    "author_association": "NONE",
    "body": "### Expected Behavior\r\n\r\nServer errors or I see a traceback. I'm trying to run a little flask app as part of a kivy frontend (goal to make a multiplayer card game app). In a later endpoint I typed `njwfnof` to simulate an error and nothing happened when the endpoint was hit. Is this intended?\r\n\r\n```python\r\nclass FlaskThread(Thread):\r\n    def __init__(self, *args, **kwargs):\r\n        self.root = kwargs.pop('root')\r\n        super().__init__(*args, **kwargs)\r\n\r\n    def run(self):\r\n        app.root = self.root\r\n        app.run(\r\n            host='127.0.0.1', port=8888, debug=True, use_debugger=True,\r\n            # setting use_reloader to False because it can't be True if not run in main thread\r\n            use_reloader=False)\r\n\r\n```\r\n\r\n### Actual Behavior\r\n\r\nServer stays up but nothing happens\r\n\r\n### Environment\r\n\r\n* Python version: 3.6.4\r\n* Flask version: Flask 1.0.2\r\n* Werkzeug version: 0.14.1\r\n",
    "comments_inline": [
        {
            "url": "https://api.github.com/repos/pallets/flask/issues/comments/439670625",
            "html_url": "https://github.com/pallets/flask/issues/2999#issuecomment-439670625",
            "issue_url": "https://api.github.com/repos/pallets/flask/issues/2999",
            "id": 439670625,
            "node_id": "MDEyOklzc3VlQ29tbWVudDQzOTY3MDYyNQ==",
            "user": {
                "login": "s1113950",
                "id": 8314343,
                "node_id": "MDQ6VXNlcjgzMTQzNDM=",
                "avatar_url": "https://avatars3.githubusercontent.com/u/8314343?v=4",
                "gravatar_id": "",
                "url": "https://api.github.com/users/s1113950",
                "html_url": "https://github.com/s1113950",
                "followers_url": "https://api.github.com/users/s1113950/followers",
                "following_url": "https://api.github.com/users/s1113950/following{/other_user}",
                "gists_url": "https://api.github.com/users/s1113950/gists{/gist_id}",
                "starred_url": "https://api.github.com/users/s1113950/starred{/owner}{/repo}",
                "subscriptions_url": "https://api.github.com/users/s1113950/subscriptions",
                "organizations_url": "https://api.github.com/users/s1113950/orgs",
                "repos_url": "https://api.github.com/users/s1113950/repos",
                "events_url": "https://api.github.com/users/s1113950/events{/privacy}",
                "received_events_url": "https://api.github.com/users/s1113950/received_events",
                "type": "User",
                "site_admin": false
            },
            "created_at": "2018-11-18T06:14:52Z",
            "updated_at": "2018-11-18T06:14:52Z",
            "author_association": "NONE",
            "body": "When I stepped through it with `pdb` though I did see errors \ud83e\udd14 "
        },
        {
            "url": "https://api.github.com/repos/pallets/flask/issues/comments/439675434",
            "html_url": "https://github.com/pallets/flask/issues/2999#issuecomment-439675434",
            "issue_url": "https://api.github.com/repos/pallets/flask/issues/2999",
            "id": 439675434,
            "node_id": "MDEyOklzc3VlQ29tbWVudDQzOTY3NTQzNA==",
            "user": {
                "login": "miguelgrinberg",
                "id": 2715854,
                "node_id": "MDQ6VXNlcjI3MTU4NTQ=",
                "avatar_url": "https://avatars0.githubusercontent.com/u/2715854?v=4",
                "gravatar_id": "",
                "url": "https://api.github.com/users/miguelgrinberg",
                "html_url": "https://github.com/miguelgrinberg",
                "followers_url": "https://api.github.com/users/miguelgrinberg/followers",
                "following_url": "https://api.github.com/users/miguelgrinberg/following{/other_user}",
                "gists_url": "https://api.github.com/users/miguelgrinberg/gists{/gist_id}",
                "starred_url": "https://api.github.com/users/miguelgrinberg/starred{/owner}{/repo}",
                "subscriptions_url": "https://api.github.com/users/miguelgrinberg/subscriptions",
                "organizations_url": "https://api.github.com/users/miguelgrinberg/orgs",
                "repos_url": "https://api.github.com/users/miguelgrinberg/repos",
                "events_url": "https://api.github.com/users/miguelgrinberg/events{/privacy}",
                "received_events_url": "https://api.github.com/users/miguelgrinberg/received_events",
                "type": "User",
                "site_admin": false
            },
            "created_at": "2018-11-18T08:16:16Z",
            "updated_at": "2018-11-18T08:16:16Z",
            "author_association": "MEMBER",
            "body": "What errors did you see in pdb?"
        },
        {
            "url": "https://api.github.com/repos/pallets/flask/issues/comments/439709837",
            "html_url": "https://github.com/pallets/flask/issues/2999#issuecomment-439709837",
            "issue_url": "https://api.github.com/repos/pallets/flask/issues/2999",
            "id": 439709837,
            "node_id": "MDEyOklzc3VlQ29tbWVudDQzOTcwOTgzNw==",
            "user": {
                "login": "s1113950",
                "id": 8314343,
                "node_id": "MDQ6VXNlcjgzMTQzNDM=",
                "avatar_url": "https://avatars3.githubusercontent.com/u/8314343?v=4",
                "gravatar_id": "",
                "url": "https://api.github.com/users/s1113950",
                "html_url": "https://github.com/s1113950",
                "followers_url": "https://api.github.com/users/s1113950/followers",
                "following_url": "https://api.github.com/users/s1113950/following{/other_user}",
                "gists_url": "https://api.github.com/users/s1113950/gists{/gist_id}",
                "starred_url": "https://api.github.com/users/s1113950/starred{/owner}{/repo}",
                "subscriptions_url": "https://api.github.com/users/s1113950/subscriptions",
                "organizations_url": "https://api.github.com/users/s1113950/orgs",
                "repos_url": "https://api.github.com/users/s1113950/repos",
                "events_url": "https://api.github.com/users/s1113950/events{/privacy}",
                "received_events_url": "https://api.github.com/users/s1113950/received_events",
                "type": "User",
                "site_admin": false
            },
            "created_at": "2018-11-18T17:24:49Z",
            "updated_at": "2018-11-18T17:24:49Z",
            "author_association": "NONE",
            "body": "Any kind of error is masked it seems. Syntaxerror when I deliberately threw an error to verify, but also AttributeError initially when I had accidentally called the wrong function. Pdb shows a normal error message when I were to `step` through the bad endpoint"
        },
        {
            "url": "https://api.github.com/repos/pallets/flask/issues/comments/439716388",
            "html_url": "https://github.com/pallets/flask/issues/2999#issuecomment-439716388",
            "issue_url": "https://api.github.com/repos/pallets/flask/issues/2999",
            "id": 439716388,
            "node_id": "MDEyOklzc3VlQ29tbWVudDQzOTcxNjM4OA==",
            "user": {
                "login": "davidism",
                "id": 1242887,
                "node_id": "MDQ6VXNlcjEyNDI4ODc=",
                "avatar_url": "https://avatars1.githubusercontent.com/u/1242887?v=4",
                "gravatar_id": "",
                "url": "https://api.github.com/users/davidism",
                "html_url": "https://github.com/davidism",
                "followers_url": "https://api.github.com/users/davidism/followers",
                "following_url": "https://api.github.com/users/davidism/following{/other_user}",
                "gists_url": "https://api.github.com/users/davidism/gists{/gist_id}",
                "starred_url": "https://api.github.com/users/davidism/starred{/owner}{/repo}",
                "subscriptions_url": "https://api.github.com/users/davidism/subscriptions",
                "organizations_url": "https://api.github.com/users/davidism/orgs",
                "repos_url": "https://api.github.com/users/davidism/repos",
                "events_url": "https://api.github.com/users/davidism/events{/privacy}",
                "received_events_url": "https://api.github.com/users/davidism/received_events",
                "type": "User",
                "site_admin": false
            },
            "created_at": "2018-11-18T18:57:10Z",
            "updated_at": "2018-11-18T18:57:10Z",
            "author_association": "MEMBER",
            "body": "Are you saying you don't get a 500 response when you raise an error? You haven't given very much direct reproducible information, and there are a lot of details that may be unnecessary, such as running with Kivy. Please add a full minimal reproducible example."
        },
        {
            "url": "https://api.github.com/repos/pallets/flask/issues/comments/439770574",
            "html_url": "https://github.com/pallets/flask/issues/2999#issuecomment-439770574",
            "issue_url": "https://api.github.com/repos/pallets/flask/issues/2999",
            "id": 439770574,
            "node_id": "MDEyOklzc3VlQ29tbWVudDQzOTc3MDU3NA==",
            "user": {
                "login": "s1113950",
                "id": 8314343,
                "node_id": "MDQ6VXNlcjgzMTQzNDM=",
                "avatar_url": "https://avatars3.githubusercontent.com/u/8314343?v=4",
                "gravatar_id": "",
                "url": "https://api.github.com/users/s1113950",
                "html_url": "https://github.com/s1113950",
                "followers_url": "https://api.github.com/users/s1113950/followers",
                "following_url": "https://api.github.com/users/s1113950/following{/other_user}",
                "gists_url": "https://api.github.com/users/s1113950/gists{/gist_id}",
                "starred_url": "https://api.github.com/users/s1113950/starred{/owner}{/repo}",
                "subscriptions_url": "https://api.github.com/users/s1113950/subscriptions",
                "organizations_url": "https://api.github.com/users/s1113950/orgs",
                "repos_url": "https://api.github.com/users/s1113950/repos",
                "events_url": "https://api.github.com/users/s1113950/events{/privacy}",
                "received_events_url": "https://api.github.com/users/s1113950/received_events",
                "type": "User",
                "site_admin": false
            },
            "created_at": "2018-11-19T04:46:56Z",
            "updated_at": "2018-11-19T04:49:55Z",
            "author_association": "NONE",
            "body": "My bad, here are better examples. First one works just fine and doesn't use Kivy:\r\n```python\r\nimport time\r\nfrom threading import Thread\r\nfrom flask import Flask, jsonify, request\r\n\r\napp = Flask(__name__)\r\n\r\n\r\n@app.errorhandler(Exception)\r\ndef error_handler(e):\r\n    return \"Unknown Error\", 500\r\n\r\n\r\n@app.route('/test', methods=['GET'])\r\ndef test():\r\n    \"\"\"\r\n    Test endpoint to show breakage\r\n    \"\"\"\r\n    AAAAAA\r\n    return jsonify(True)\r\n\r\n\r\nclass FlaskThread(Thread):\r\n    def run(self):\r\n        app.run(\r\n            host='127.0.0.1', port=8888, debug=True, use_debugger=True,\r\n            use_reloader=False)\r\n\r\n\r\ndef main():\r\n    server = FlaskThread()\r\n    server.daemon = True\r\n    server.start()\r\n\r\n    # simulate doing something else while flask runs in background\r\n    time.sleep(100000)\r\n\r\n\r\nif __name__ == '__main__':\r\n    main()\r\n```\r\n\r\nAnd it errors as expected\r\n```\r\n* Serving Flask app \"flask_broken\" (lazy loading)\r\n * Environment: production\r\n   WARNING: Do not use the development server in a production environment.\r\n   Use a production WSGI server instead.\r\n * Debug mode: on\r\n * Running on http://127.0.0.1:8888/ (Press CTRL+C to quit)\r\n127.0.0.1 - - [18/Nov/2018 20:28:14] \"GET /test HTTP/1.1\" 500 -\r\n```\r\n\r\n```\r\nrobertso@robertso-mac02: $ curl 127.0.0.1:8888/test\r\nUnknown Errorrobertso@robertso-mac02:$\r\n```\r\n\r\nNext one is using Kivy and errors when hit with curl but doesn't show any error on the flask side:\r\n```python\r\nimport time\r\nfrom threading import Thread\r\n\r\nfrom kivy.app import App\r\nfrom flask import Flask, jsonify, request\r\n\r\napp = Flask(__name__)\r\n\r\n\r\n@app.errorhandler(Exception)\r\ndef error_handler(e):\r\n    return \"Unknown Error\", 500\r\n\r\n\r\n@app.route('/test', methods=['GET'])\r\ndef test():\r\n    \"\"\"\r\n    Test endpoint to show breakage\r\n    \"\"\"\r\n    AAAAAA\r\n    return jsonify(True)\r\n\r\n\r\nclass FlaskThread(Thread):\r\n    def run(self):\r\n        app.run(\r\n            host='127.0.0.1', port=8888, debug=True, use_debugger=True,\r\n            use_reloader=False)\r\n\r\n\r\nclass SomeApp(App):\r\n    def build(self):\r\n        server = FlaskThread()\r\n        server.daemon = True\r\n        server.start()\r\n\r\n        # simulate doing something else while flask runs in background\r\n        time.sleep(100000)\r\n\r\n\r\nif __name__ == '__main__':\r\n    SomeApp().build()\r\n```\r\n\r\nI see this:\r\n```\r\nrobertso@robertso-mac02:~$ python flask_broken.py\r\n[INFO   ] [Logger      ] Record log in /Users/robertso/.kivy/logs/kivy_18-11-18_32.txt\r\n[INFO   ] [Kivy        ] v1.10.1.dev0, git-Unknown, 20180529\r\n[INFO   ] [Python      ] v3.6.4 (default, Mar  1 2018, 18:36:42)\r\n[GCC 4.2.1 Compatible Apple LLVM 9.0.0 (clang-900.0.39.2)]\r\n[INFO   ] [Factory     ] 194 symbols loaded\r\n[INFO   ] [Image       ] Providers: img_tex, img_imageio, img_dds, img_sdl2, img_gif (img_pil, img_ffpyplayer ignored)\r\n * Serving Flask app \"flask_broken\" (lazy loading)\r\n * Environment: production\r\n   WARNING: Do not use the development server in a production environment.\r\n   Use a production WSGI server instead.\r\n * Debug mode: on\r\n```\r\nand then this on the curl side as expected:\r\n```\r\nrobertso@robertso-mac02: $ curl 127.0.0.1:8888/test\r\nUnknown Errorrobertso@robertso-mac02:$\r\n```\r\n\r\nJust noticed that with Kivy I also don't see the `Running on...` message from Flask as well. Additionally, If I add a `print` message before the `AAAAA` in the `/test` endpoint I do see that in the console."
        },
        {
            "url": "https://api.github.com/repos/pallets/flask/issues/comments/439775850",
            "html_url": "https://github.com/pallets/flask/issues/2999#issuecomment-439775850",
            "issue_url": "https://api.github.com/repos/pallets/flask/issues/2999",
            "id": 439775850,
            "node_id": "MDEyOklzc3VlQ29tbWVudDQzOTc3NTg1MA==",
            "user": {
                "login": "s1113950",
                "id": 8314343,
                "node_id": "MDQ6VXNlcjgzMTQzNDM=",
                "avatar_url": "https://avatars3.githubusercontent.com/u/8314343?v=4",
                "gravatar_id": "",
                "url": "https://api.github.com/users/s1113950",
                "html_url": "https://github.com/s1113950",
                "followers_url": "https://api.github.com/users/s1113950/followers",
                "following_url": "https://api.github.com/users/s1113950/following{/other_user}",
                "gists_url": "https://api.github.com/users/s1113950/gists{/gist_id}",
                "starred_url": "https://api.github.com/users/s1113950/starred{/owner}{/repo}",
                "subscriptions_url": "https://api.github.com/users/s1113950/subscriptions",
                "organizations_url": "https://api.github.com/users/s1113950/orgs",
                "repos_url": "https://api.github.com/users/s1113950/repos",
                "events_url": "https://api.github.com/users/s1113950/events{/privacy}",
                "received_events_url": "https://api.github.com/users/s1113950/received_events",
                "type": "User",
                "site_admin": false
            },
            "created_at": "2018-11-19T05:28:28Z",
            "updated_at": "2018-11-19T05:28:28Z",
            "author_association": "NONE",
            "body": "I also changed the title to better reflect the issue. It could be something I don't understand \ud83d\ude1e (internals of Kivy logging level that interferes with flask logging level?) but running flask with kivy also doesn't have successful request info printed out"
        },
        {
            "url": "https://api.github.com/repos/pallets/flask/issues/comments/439781527",
            "html_url": "https://github.com/pallets/flask/issues/2999#issuecomment-439781527",
            "issue_url": "https://api.github.com/repos/pallets/flask/issues/2999",
            "id": 439781527,
            "node_id": "MDEyOklzc3VlQ29tbWVudDQzOTc4MTUyNw==",
            "user": {
                "login": "RonnyPfannschmidt",
                "id": 156838,
                "node_id": "MDQ6VXNlcjE1NjgzOA==",
                "avatar_url": "https://avatars1.githubusercontent.com/u/156838?v=4",
                "gravatar_id": "",
                "url": "https://api.github.com/users/RonnyPfannschmidt",
                "html_url": "https://github.com/RonnyPfannschmidt",
                "followers_url": "https://api.github.com/users/RonnyPfannschmidt/followers",
                "following_url": "https://api.github.com/users/RonnyPfannschmidt/following{/other_user}",
                "gists_url": "https://api.github.com/users/RonnyPfannschmidt/gists{/gist_id}",
                "starred_url": "https://api.github.com/users/RonnyPfannschmidt/starred{/owner}{/repo}",
                "subscriptions_url": "https://api.github.com/users/RonnyPfannschmidt/subscriptions",
                "organizations_url": "https://api.github.com/users/RonnyPfannschmidt/orgs",
                "repos_url": "https://api.github.com/users/RonnyPfannschmidt/repos",
                "events_url": "https://api.github.com/users/RonnyPfannschmidt/events{/privacy}",
                "received_events_url": "https://api.github.com/users/RonnyPfannschmidt/received_events",
                "type": "User",
                "site_admin": false
            },
            "created_at": "2018-11-19T06:07:03Z",
            "updated_at": "2018-11-19T06:07:03Z",
            "author_association": "CONTRIBUTOR",
            "body": "i strongly suspect that the kivy logging setup might in turn cause flask not to apply its default logging setup as logging was \"set up\" by kivy - but i am completely unfamiliar with kivy"
        },
        {
            "url": "https://api.github.com/repos/pallets/flask/issues/comments/439787496",
            "html_url": "https://github.com/pallets/flask/issues/2999#issuecomment-439787496",
            "issue_url": "https://api.github.com/repos/pallets/flask/issues/2999",
            "id": 439787496,
            "node_id": "MDEyOklzc3VlQ29tbWVudDQzOTc4NzQ5Ng==",
            "user": {
                "login": "s1113950",
                "id": 8314343,
                "node_id": "MDQ6VXNlcjgzMTQzNDM=",
                "avatar_url": "https://avatars3.githubusercontent.com/u/8314343?v=4",
                "gravatar_id": "",
                "url": "https://api.github.com/users/s1113950",
                "html_url": "https://github.com/s1113950",
                "followers_url": "https://api.github.com/users/s1113950/followers",
                "following_url": "https://api.github.com/users/s1113950/following{/other_user}",
                "gists_url": "https://api.github.com/users/s1113950/gists{/gist_id}",
                "starred_url": "https://api.github.com/users/s1113950/starred{/owner}{/repo}",
                "subscriptions_url": "https://api.github.com/users/s1113950/subscriptions",
                "organizations_url": "https://api.github.com/users/s1113950/orgs",
                "repos_url": "https://api.github.com/users/s1113950/repos",
                "events_url": "https://api.github.com/users/s1113950/events{/privacy}",
                "received_events_url": "https://api.github.com/users/s1113950/received_events",
                "type": "User",
                "site_admin": false
            },
            "created_at": "2018-11-19T06:43:41Z",
            "updated_at": "2018-11-19T06:43:41Z",
            "author_association": "NONE",
            "body": "aHa! I found it: https://github.com/kivy/kivy/blob/master/kivy/logger.py#L324 yeah looks like kivy's logger is blocking other loggers, since `flask` logs things under the `flask` namespace. Time to close this issue!"
        },
        {
            "url": "https://api.github.com/repos/pallets/flask/issues/comments/439788463",
            "html_url": "https://github.com/pallets/flask/issues/2999#issuecomment-439788463",
            "issue_url": "https://api.github.com/repos/pallets/flask/issues/2999",
            "id": 439788463,
            "node_id": "MDEyOklzc3VlQ29tbWVudDQzOTc4ODQ2Mw==",
            "user": {
                "login": "RonnyPfannschmidt",
                "id": 156838,
                "node_id": "MDQ6VXNlcjE1NjgzOA==",
                "avatar_url": "https://avatars1.githubusercontent.com/u/156838?v=4",
                "gravatar_id": "",
                "url": "https://api.github.com/users/RonnyPfannschmidt",
                "html_url": "https://github.com/RonnyPfannschmidt",
                "followers_url": "https://api.github.com/users/RonnyPfannschmidt/followers",
                "following_url": "https://api.github.com/users/RonnyPfannschmidt/following{/other_user}",
                "gists_url": "https://api.github.com/users/RonnyPfannschmidt/gists{/gist_id}",
                "starred_url": "https://api.github.com/users/RonnyPfannschmidt/starred{/owner}{/repo}",
                "subscriptions_url": "https://api.github.com/users/RonnyPfannschmidt/subscriptions",
                "organizations_url": "https://api.github.com/users/RonnyPfannschmidt/orgs",
                "repos_url": "https://api.github.com/users/RonnyPfannschmidt/repos",
                "events_url": "https://api.github.com/users/RonnyPfannschmidt/events{/privacy}",
                "received_events_url": "https://api.github.com/users/RonnyPfannschmidt/received_events",
                "type": "User",
                "site_admin": false
            },
            "created_at": "2018-11-19T06:48:58Z",
            "updated_at": "2018-11-19T06:48:58Z",
            "author_association": "CONTRIBUTOR",
            "body": "wow that just totally bad of kivy"
        },
        {
            "url": "https://api.github.com/repos/pallets/flask/issues/comments/439788603",
            "html_url": "https://github.com/pallets/flask/issues/2999#issuecomment-439788603",
            "issue_url": "https://api.github.com/repos/pallets/flask/issues/2999",
            "id": 439788603,
            "node_id": "MDEyOklzc3VlQ29tbWVudDQzOTc4ODYwMw==",
            "user": {
                "login": "s1113950",
                "id": 8314343,
                "node_id": "MDQ6VXNlcjgzMTQzNDM=",
                "avatar_url": "https://avatars3.githubusercontent.com/u/8314343?v=4",
                "gravatar_id": "",
                "url": "https://api.github.com/users/s1113950",
                "html_url": "https://github.com/s1113950",
                "followers_url": "https://api.github.com/users/s1113950/followers",
                "following_url": "https://api.github.com/users/s1113950/following{/other_user}",
                "gists_url": "https://api.github.com/users/s1113950/gists{/gist_id}",
                "starred_url": "https://api.github.com/users/s1113950/starred{/owner}{/repo}",
                "subscriptions_url": "https://api.github.com/users/s1113950/subscriptions",
                "organizations_url": "https://api.github.com/users/s1113950/orgs",
                "repos_url": "https://api.github.com/users/s1113950/repos",
                "events_url": "https://api.github.com/users/s1113950/events{/privacy}",
                "received_events_url": "https://api.github.com/users/s1113950/received_events",
                "type": "User",
                "site_admin": false
            },
            "created_at": "2018-11-19T06:49:48Z",
            "updated_at": "2018-11-19T06:49:48Z",
            "author_association": "NONE",
            "body": "I'm going to file an issue on Kivy about it"
        },
        {
            "url": "https://api.github.com/repos/pallets/flask/issues/comments/439797182",
            "html_url": "https://github.com/pallets/flask/issues/2999#issuecomment-439797182",
            "issue_url": "https://api.github.com/repos/pallets/flask/issues/2999",
            "id": 439797182,
            "node_id": "MDEyOklzc3VlQ29tbWVudDQzOTc5NzE4Mg==",
            "user": {
                "login": "s1113950",
                "id": 8314343,
                "node_id": "MDQ6VXNlcjgzMTQzNDM=",
                "avatar_url": "https://avatars3.githubusercontent.com/u/8314343?v=4",
                "gravatar_id": "",
                "url": "https://api.github.com/users/s1113950",
                "html_url": "https://github.com/s1113950",
                "followers_url": "https://api.github.com/users/s1113950/followers",
                "following_url": "https://api.github.com/users/s1113950/following{/other_user}",
                "gists_url": "https://api.github.com/users/s1113950/gists{/gist_id}",
                "starred_url": "https://api.github.com/users/s1113950/starred{/owner}{/repo}",
                "subscriptions_url": "https://api.github.com/users/s1113950/subscriptions",
                "organizations_url": "https://api.github.com/users/s1113950/orgs",
                "repos_url": "https://api.github.com/users/s1113950/repos",
                "events_url": "https://api.github.com/users/s1113950/events{/privacy}",
                "received_events_url": "https://api.github.com/users/s1113950/received_events",
                "type": "User",
                "site_admin": false
            },
            "created_at": "2018-11-19T07:34:07Z",
            "updated_at": "2018-11-19T07:39:33Z",
            "author_association": "NONE",
            "body": "Here's a workaround to anyone who runs into this too, which turns back on logging in flask when running Kivy (editing my example above):\r\n```python\r\nfrom logging import Logger\r\n\r\nclass FlaskThread(Thread):\r\n    def run(self):\r\n        Logger.manager.loggerDict['werkzeug'] = Logger.manager.loggerDict['kivy']\r\n        app.run(\r\n            host='127.0.0.1', port=8888, debug=True, use_debugger=True,\r\n            use_reloader=False)\r\n```\r\n\ud83e\udd26\u200d\u2642\ufe0f "
        },
        {
            "url": "https://api.github.com/repos/pallets/flask/issues/comments/439830036",
            "html_url": "https://github.com/pallets/flask/issues/2999#issuecomment-439830036",
            "issue_url": "https://api.github.com/repos/pallets/flask/issues/2999",
            "id": 439830036,
            "node_id": "MDEyOklzc3VlQ29tbWVudDQzOTgzMDAzNg==",
            "user": {
                "login": "miguelgrinberg",
                "id": 2715854,
                "node_id": "MDQ6VXNlcjI3MTU4NTQ=",
                "avatar_url": "https://avatars0.githubusercontent.com/u/2715854?v=4",
                "gravatar_id": "",
                "url": "https://api.github.com/users/miguelgrinberg",
                "html_url": "https://github.com/miguelgrinberg",
                "followers_url": "https://api.github.com/users/miguelgrinberg/followers",
                "following_url": "https://api.github.com/users/miguelgrinberg/following{/other_user}",
                "gists_url": "https://api.github.com/users/miguelgrinberg/gists{/gist_id}",
                "starred_url": "https://api.github.com/users/miguelgrinberg/starred{/owner}{/repo}",
                "subscriptions_url": "https://api.github.com/users/miguelgrinberg/subscriptions",
                "organizations_url": "https://api.github.com/users/miguelgrinberg/orgs",
                "repos_url": "https://api.github.com/users/miguelgrinberg/repos",
                "events_url": "https://api.github.com/users/miguelgrinberg/events{/privacy}",
                "received_events_url": "https://api.github.com/users/miguelgrinberg/received_events",
                "type": "User",
                "site_admin": false
            },
            "created_at": "2018-11-19T09:39:15Z",
            "updated_at": "2018-11-19T09:41:57Z",
            "author_association": "MEMBER",
            "body": "@s1113950 hey, I just noticed that you had the debugger enabled in these tests. Did the in-browser debugger appear when an error occurred, or is this also something that needs to be investigated? What did you have `FLASK_ENV` set to?"
        },
        {
            "url": "https://api.github.com/repos/pallets/flask/issues/comments/440216307",
            "html_url": "https://github.com/pallets/flask/issues/2999#issuecomment-440216307",
            "issue_url": "https://api.github.com/repos/pallets/flask/issues/2999",
            "id": 440216307,
            "node_id": "MDEyOklzc3VlQ29tbWVudDQ0MDIxNjMwNw==",
            "user": {
                "login": "s1113950",
                "id": 8314343,
                "node_id": "MDQ6VXNlcjgzMTQzNDM=",
                "avatar_url": "https://avatars3.githubusercontent.com/u/8314343?v=4",
                "gravatar_id": "",
                "url": "https://api.github.com/users/s1113950",
                "html_url": "https://github.com/s1113950",
                "followers_url": "https://api.github.com/users/s1113950/followers",
                "following_url": "https://api.github.com/users/s1113950/following{/other_user}",
                "gists_url": "https://api.github.com/users/s1113950/gists{/gist_id}",
                "starred_url": "https://api.github.com/users/s1113950/starred{/owner}{/repo}",
                "subscriptions_url": "https://api.github.com/users/s1113950/subscriptions",
                "organizations_url": "https://api.github.com/users/s1113950/orgs",
                "repos_url": "https://api.github.com/users/s1113950/repos",
                "events_url": "https://api.github.com/users/s1113950/events{/privacy}",
                "received_events_url": "https://api.github.com/users/s1113950/received_events",
                "type": "User",
                "site_admin": false
            },
            "created_at": "2018-11-20T10:06:58Z",
            "updated_at": "2018-11-20T10:06:58Z",
            "author_association": "NONE",
            "body": "I was using kivy so there was no browser; I'm not sure. I didn't change `FLASK_ENV` to anything in particular"
        },
        {
            "url": "https://api.github.com/repos/pallets/flask/issues/comments/440225558",
            "html_url": "https://github.com/pallets/flask/issues/2999#issuecomment-440225558",
            "issue_url": "https://api.github.com/repos/pallets/flask/issues/2999",
            "id": 440225558,
            "node_id": "MDEyOklzc3VlQ29tbWVudDQ0MDIyNTU1OA==",
            "user": {
                "login": "miguelgrinberg",
                "id": 2715854,
                "node_id": "MDQ6VXNlcjI3MTU4NTQ=",
                "avatar_url": "https://avatars0.githubusercontent.com/u/2715854?v=4",
                "gravatar_id": "",
                "url": "https://api.github.com/users/miguelgrinberg",
                "html_url": "https://github.com/miguelgrinberg",
                "followers_url": "https://api.github.com/users/miguelgrinberg/followers",
                "following_url": "https://api.github.com/users/miguelgrinberg/following{/other_user}",
                "gists_url": "https://api.github.com/users/miguelgrinberg/gists{/gist_id}",
                "starred_url": "https://api.github.com/users/miguelgrinberg/starred{/owner}{/repo}",
                "subscriptions_url": "https://api.github.com/users/miguelgrinberg/subscriptions",
                "organizations_url": "https://api.github.com/users/miguelgrinberg/orgs",
                "repos_url": "https://api.github.com/users/miguelgrinberg/repos",
                "events_url": "https://api.github.com/users/miguelgrinberg/events{/privacy}",
                "received_events_url": "https://api.github.com/users/miguelgrinberg/received_events",
                "type": "User",
                "site_admin": false
            },
            "created_at": "2018-11-20T10:36:32Z",
            "updated_at": "2018-11-20T10:36:32Z",
            "author_association": "MEMBER",
            "body": "@s1113950 actually, I missed that you have a catch-all exception handler in your test, that is why the debugger does not run for you. False alarm."
        }
    ]
}